<?xml version="1.0" encoding="utf-8"?>
<!-- This URDF was automatically created by SolidWorks to URDF Exporter! Originally created by Stephen Brawner (brawner@gmail.com) 
     Commit Version: 1.6.0-4-g7f85cfe  Build Version: 1.6.7995.38578
     For more information, please see http://wiki.ros.org/sw_urdf_exporter -->
<robot
  name="quadruped_robot">
  <link
    name="base_link">
    <inertial>
      <origin
        xyz="2.5071E-05 -0.00017258 0.020875"
        rpy="0 0 0" />
      <mass
        value="0.3417" />
      <inertia
        ixx="0.00015104"
        ixy="-1.3934E-08"
        ixz="6.3507E-08"
        iyy="0.00047549"
        iyz="2.3538E-08"
        izz="0.00055234" />
    </inertial>
    <visual>
      <origin
        xyz="0 0 0"
        rpy="0 0 0" />
      <geometry>
        <mesh
          filename="package://robot_sim/meshes/base_link.STL" />
      </geometry>
      <material
        name="">
        <color
          rgba="0.79216 0.81961 0.93333 1" />
      </material>
    </visual>
    <collision>
      <origin
        xyz="0 0 0"
        rpy="0 0 0" />
      <geometry>
        <mesh
          filename="package://robot_sim/meshes/base_link.STL" />
      </geometry>
    </collision>
  </link>
  <link
    name="servo_1_link">
    <inertial>
      <origin
        xyz="0.015 -0.006638 -0.00063935"
        rpy="0 0 0" />
      <mass
        value="0.020716" />
      <inertia
        ixx="2.6167E-06"
        ixy="-4.0064E-22"
        ixz="-1.926E-22"
        iyy="2.3693E-06"
        iyz="6.9329E-09"
        izz="3.3455E-06" />
    </inertial>
    <visual>
      <origin
        xyz="0 0 0"
        rpy="0 0 0" />
      <geometry>
        <mesh
          filename="package://robot_sim/meshes/servo_1_link.STL" />
      </geometry>
      <material
        name="">
        <color
          rgba="0.79216 0.81961 0.93333 1" />
      </material>
    </visual>
    <collision>
      <origin
        xyz="0 0 0"
        rpy="0 0 0" />
      <geometry>
        <mesh
          filename="package://robot_sim/meshes/servo_1_link.STL" />
      </geometry>
    </collision>
  </link>
  <joint
    name="servo_1_joint"
    type="continuous">
    <origin
      xyz="0.05 -0.026 0.024"
      rpy="1.19325088290338 0 0" />
    <parent
      link="base_link" />
    <child
      link="servo_1_link" />
    <axis
      xyz="1 0 0" />
  </joint>
  <link
    name="leg_1_link">
    <inertial>
      <origin
        xyz="-0.02 -6.7828E-14 0.015304"
        rpy="0 0 0" />
      <mass
        value="0.002267" />
      <inertia
        ixx="2.3718E-08"
        ixy="-1.3229E-18"
        ixz="7.6928E-23"
        iyy="4.1387E-07"
        iyz="-2.647E-23"
        izz="4.2814E-07" />
    </inertial>
    <visual>
      <origin
        xyz="0 0 0"
        rpy="0 0 0" />
      <geometry>
        <mesh
          filename="package://robot_sim/meshes/leg_1_link.STL" />
      </geometry>
      <material
        name="">
        <color
          rgba="0.79216 0.81961 0.93333 1" />
      </material>
    </visual>
    <collision>
      <origin
        xyz="0 0 0"
        rpy="0 0 0" />
      <geometry>
        <mesh
          filename="package://robot_sim/meshes/leg_1_link.STL" />
      </geometry>
    </collision>
  </link>
  <joint
    name="leg_1_joint"
    type="continuous">
    <origin
      xyz="0.015 -0.013 -0.00280397218834483"
      rpy="0 0 0.625000267634323" />
    <parent
      link="servo_1_link" />
    <child
      link="leg_1_link" />
    <axis
      xyz="0 0 -1" />
  </joint>
  <link
    name="foot_1_link">
    <inertial>
      <origin
        xyz="0.039601 0.0056225 -0.030222"
        rpy="0 0 0" />
      <mass
        value="0.0046685" />
      <inertia
        ixx="4.2091E-07"
        ixy="-7.4925E-07"
        ixz="1.2441E-08"
        iyy="2.757E-06"
        iyz="1.7664E-09"
        izz="3.1554E-06" />
    </inertial>
    <visual>
      <origin
        xyz="0 0 0"
        rpy="0 0 0" />
      <geometry>
        <mesh
          filename="package://robot_sim/meshes/foot_1_link.STL" />
      </geometry>
      <material
        name="">
        <color
          rgba="0.79216 0.81961 0.93333 1" />
      </material>
    </visual>
    <collision>
      <origin
        xyz="0 0 0"
        rpy="0 0 0" />
      <geometry>
        <mesh
          filename="package://robot_sim/meshes/foot_1_link.STL" />
      </geometry>
    </collision>
  </link>
  <joint
    name="foot_1_joint"
    type="continuous">
    <origin
      xyz="-0.04 0 -0.00998527475373712"
      rpy="3.14159265358979 0 -1.04037357500652" />
    <parent
      link="leg_1_link" />
    <child
      link="foot_1_link" />
    <axis
      xyz="0 0 1" />
  </joint>
  <link
    name="servo_2_link">
    <inertial>
      <origin
        xyz="-0.015 -0.006638 -0.00063935"
        rpy="0 0 0" />
      <mass
        value="0.020716" />
      <inertia
        ixx="2.6167E-06"
        ixy="2.9556E-22"
        ixz="-5.0625E-23"
        iyy="2.3693E-06"
        iyz="6.9329E-09"
        izz="3.3455E-06" />
    </inertial>
    <visual>
      <origin
        xyz="0 0 0"
        rpy="0 0 0" />
      <geometry>
        <mesh
          filename="package://robot_sim/meshes/servo_2_link.STL" />
      </geometry>
      <material
        name="">
        <color
          rgba="0.79216 0.81961 0.93333 1" />
      </material>
    </visual>
    <collision>
      <origin
        xyz="0 0 0"
        rpy="0 0 0" />
      <geometry>
        <mesh
          filename="package://robot_sim/meshes/servo_2_link.STL" />
      </geometry>
    </collision>
  </link>
  <joint
    name="servo_2_joint"
    type="continuous">
    <origin
      xyz="-0.05 -0.026 0.024"
      rpy="1.38644147063987 0 0" />
    <parent
      link="base_link" />
    <child
      link="servo_2_link" />
    <axis
      xyz="1 0 0" />
  </joint>
  <link
    name="leg_2_link">
    <inertial>
      <origin
        xyz="-0.02 -2.498E-16 0.0095174"
        rpy="0 0 0" />
      <mass
        value="0.002267" />
      <inertia
        ixx="2.3718E-08"
        ixy="1.5882E-22"
        ixz="-1.6812E-22"
        iyy="4.1387E-07"
        iyz="-1.9852E-23"
        izz="4.2814E-07" />
    </inertial>
    <visual>
      <origin
        xyz="0 0 0"
        rpy="0 0 0" />
      <geometry>
        <mesh
          filename="package://robot_sim/meshes/leg_2_link.STL" />
      </geometry>
      <material
        name="">
        <color
          rgba="0.79216 0.81961 0.93333 1" />
      </material>
    </visual>
    <collision>
      <origin
        xyz="0 0 0"
        rpy="0 0 0" />
      <geometry>
        <mesh
          filename="package://robot_sim/meshes/leg_2_link.STL" />
      </geometry>
    </collision>
  </link>
  <joint
    name="leg_2_joint"
    type="continuous">
    <origin
      xyz="-0.015 -0.013 0.00298261436575352"
      rpy="0 0 0.671619943025242" />
    <parent
      link="servo_2_link" />
    <child
      link="leg_2_link" />
    <axis
      xyz="0 0 -1" />
  </joint>
  <link
    name="foot_2_link">
    <inertial>
      <origin
        xyz="0.039601 0.0056225 -0.019364"
        rpy="0 0 0" />
      <mass
        value="0.0046685" />
      <inertia
        ixx="4.2091E-07"
        ixy="-7.4925E-07"
        ixz="1.2441E-08"
        iyy="2.757E-06"
        iyz="1.7664E-09"
        izz="3.1554E-06" />
    </inertial>
    <visual>
      <origin
        xyz="0 0 0"
        rpy="0 0 0" />
      <geometry>
        <mesh
          filename="package://robot_sim/meshes/foot_2_link.STL" />
      </geometry>
      <material
        name="">
        <color
          rgba="0.79216 0.81961 0.93333 1" />
      </material>
    </visual>
    <collision>
      <origin
        xyz="0 0 0"
        rpy="0 0 0" />
      <geometry>
        <mesh
          filename="package://robot_sim/meshes/foot_2_link.STL" />
      </geometry>
    </collision>
  </link>
  <joint
    name="foot_2_joint"
    type="continuous">
    <origin
      xyz="-0.0399999999999991 0 -0.0049140967243233"
      rpy="-3.14159265358979 0 -1.08209164870542" />
    <parent
      link="leg_2_link" />
    <child
      link="foot_2_link" />
    <axis
      xyz="0 0 1" />
  </joint>
  <link
    name="servo_3_link">
    <inertial>
      <origin
        xyz="0.015 -0.006638 -0.00063935"
        rpy="0 0 0" />
      <mass
        value="0.020716" />
      <inertia
        ixx="2.6167E-06"
        ixy="1.2835E-22"
        ixz="8.8166E-23"
        iyy="2.3693E-06"
        iyz="6.9329E-09"
        izz="3.3455E-06" />
    </inertial>
    <visual>
      <origin
        xyz="0 0 0"
        rpy="0 0 0" />
      <geometry>
        <mesh
          filename="package://robot_sim/meshes/servo_3_link.STL" />
      </geometry>
      <material
        name="">
        <color
          rgba="0.79216 0.81961 0.93333 1" />
      </material>
    </visual>
    <collision>
      <origin
        xyz="0 0 0"
        rpy="0 0 0" />
      <geometry>
        <mesh
          filename="package://robot_sim/meshes/servo_3_link.STL" />
      </geometry>
    </collision>
  </link>
  <joint
    name="servo_3_joint"
    type="continuous">
    <origin
      xyz="-0.05 0.0259999999999996 0.0240000000000004"
      rpy="1.43932790895367 0 3.14159265358979" />
    <parent
      link="base_link" />
    <child
      link="servo_3_link" />
    <axis
      xyz="-1 0 0" />
  </joint>
  <link
    name="leg_3_link">
    <inertial>
      <origin
        xyz="0.02 0 0.0024141"
        rpy="0 0 0" />
      <mass
        value="0.002267" />
      <inertia
        ixx="2.3718E-08"
        ixy="-1.4145E-22"
        ixz="-4.26E-23"
        iyy="4.1387E-07"
        iyz="-3.3087E-24"
        izz="4.2814E-07" />
    </inertial>
    <visual>
      <origin
        xyz="0 0 0"
        rpy="0 0 0" />
      <geometry>
        <mesh
          filename="package://robot_sim/meshes/leg_3_link.STL" />
      </geometry>
      <material
        name="">
        <color
          rgba="0.79216 0.81961 0.93333 1" />
      </material>
    </visual>
    <collision>
      <origin
        xyz="0 0 0"
        rpy="0 0 0" />
      <geometry>
        <mesh
          filename="package://robot_sim/meshes/leg_3_link.STL" />
      </geometry>
    </collision>
  </link>
  <joint
    name="leg_3_joint"
    type="continuous">
    <origin
      xyz="0.0149999999999994 -0.0129999999999998 0.0100859229791846"
      rpy="0 0 -0.524206506794894" />
    <parent
      link="servo_3_link" />
    <child
      link="leg_3_link" />
    <axis
      xyz="0 0 1" />
  </joint>
  <link
    name="foot_3_link">
    <inertial>
      <origin
        xyz="-0.039601 0.0056225 -0.0073468"
        rpy="0 0 0" />
      <mass
        value="0.0046685" />
      <inertia
        ixx="4.2091E-07"
        ixy="7.4925E-07"
        ixz="-1.2441E-08"
        iyy="2.757E-06"
        iyz="1.7664E-09"
        izz="3.1554E-06" />
    </inertial>
    <visual>
      <origin
        xyz="0 0 0"
        rpy="0 0 0" />
      <geometry>
        <mesh
          filename="package://robot_sim/meshes/foot_3_link.STL" />
      </geometry>
      <material
        name="">
        <color
          rgba="0.79216 0.81961 0.93333 1" />
      </material>
    </visual>
    <collision>
      <origin
        xyz="0 0 0"
        rpy="0 0 0" />
      <geometry>
        <mesh
          filename="package://robot_sim/meshes/foot_3_link.STL" />
      </geometry>
    </collision>
  </link>
  <joint
    name="foot_3_joint"
    type="continuous">
    <origin
      xyz="0.04 0 0"
      rpy="-3.14159265358979 0 1.07982204879055" />
    <parent
      link="leg_3_link" />
    <child
      link="foot_3_link" />
    <axis
      xyz="0 0 -1" />
  </joint>
  <link
    name="servo_4_link">
    <inertial>
      <origin
        xyz="-0.015 -0.006638 -0.00063935"
        rpy="0 0 0" />
      <mass
        value="0.020716" />
      <inertia
        ixx="2.6167E-06"
        ixy="-9.6289E-23"
        ixz="1.5371E-22"
        iyy="2.3693E-06"
        iyz="6.9329E-09"
        izz="3.3455E-06" />
    </inertial>
    <visual>
      <origin
        xyz="0 0 0"
        rpy="0 0 0" />
      <geometry>
        <mesh
          filename="package://robot_sim/meshes/servo_4_link.STL" />
      </geometry>
      <material
        name="">
        <color
          rgba="0.79216 0.81961 0.93333 1" />
      </material>
    </visual>
    <collision>
      <origin
        xyz="0 0 0"
        rpy="0 0 0" />
      <geometry>
        <mesh
          filename="package://robot_sim/meshes/servo_4_link.STL" />
      </geometry>
    </collision>
  </link>
  <joint
    name="servo_4_joints"
    type="continuous">
    <origin
      xyz="0.05 0.0259999999999998 0.0239999999999998"
      rpy="1.2521204794546 0 3.14159265358979" />
    <parent
      link="base_link" />
    <child
      link="servo_4_link" />
    <axis
      xyz="-1 0 0" />
  </joint>
  <link
    name="leg_4_link">
    <inertial>
      <origin
        xyz="0.02 0 0.0020092"
        rpy="0 0 0" />
      <mass
        value="0.002267" />
      <inertia
        ixx="2.3718E-08"
        ixy="6.6174E-23"
        ixz="1.613E-22"
        iyy="4.1387E-07"
        iyz="-6.6174E-24"
        izz="4.2814E-07" />
    </inertial>
    <visual>
      <origin
        xyz="0 0 0"
        rpy="0 0 0" />
      <geometry>
        <mesh
          filename="package://robot_sim/meshes/leg_4_link.STL" />
      </geometry>
      <material
        name="">
        <color
          rgba="0.79216 0.81961 0.93333 1" />
      </material>
    </visual>
    <collision>
      <origin
        xyz="0 0 0"
        rpy="0 0 0" />
      <geometry>
        <mesh
          filename="package://robot_sim/meshes/leg_4_link.STL" />
      </geometry>
    </collision>
  </link>
  <joint
    name="leg_4_joint"
    type="continuous">
    <origin
      xyz="-0.0150000000000001 -0.013 0.0104908137521414"
      rpy="0 0 -0.625428082238554" />
    <parent
      link="servo_4_link" />
    <child
      link="leg_4_link" />
    <axis
      xyz="0 0 1" />
  </joint>
  <link
    name="foot_4_link">
    <inertial>
      <origin
        xyz="-0.039601 0.0056225 -0.0069419"
        rpy="0 0 0" />
      <mass
        value="0.0046685" />
      <inertia
        ixx="4.2091E-07"
        ixy="7.4925E-07"
        ixz="-1.2441E-08"
        iyy="2.757E-06"
        iyz="1.7664E-09"
        izz="3.1554E-06" />
    </inertial>
    <visual>
      <origin
        xyz="0 0 0"
        rpy="0 0 0" />
      <geometry>
        <mesh
          filename="package://robot_sim/meshes/foot_4_link.STL" />
      </geometry>
      <material
        name="">
        <color
          rgba="0.79216 0.81961 0.93333 1" />
      </material>
    </visual>
    <collision>
      <origin
        xyz="0 0 0"
        rpy="0 0 0" />
      <geometry>
        <mesh
          filename="package://robot_sim/meshes/foot_4_link.STL" />
      </geometry>
    </collision>
  </link>
  <joint
    name="foot_4_joint"
    type="continuous">
    <origin
      xyz="0.04 0 0"
      rpy="-3.14159265358979 0 1.20568652407404" />
    <parent
      link="leg_4_link" />
    <child
      link="foot_4_link" />
    <axis
      xyz="0 0 -1" />
  </joint>
</robot>